Workbook

Sheet RESUMO
C1: YAD FILMES PRODUÇÕES AUDIOVISUAIS LTDA
C2: Av. Queiroz Filho, 1700 — Vila Hamburguesa, São Paulo — SP
C3: CNPJ 45.622.704/0001-34
C4: yadfilmes.com · @yadfilmes · (12) 99119-0186
B7: PRESSUPOSTO REAL
B8: AMIRA — Live profissional · captação, operação e transmissão
B9: Cliente: AMIRA · Período: evento 8h às 13h · 1 diária · montagem, configuração, testes, operação e desmontagem
B11: Elaborado por | C11: Felype · felype@yadfilmes.com.br | E11: Em | F11: 46254
B12: Atualizado por | C12: Felype · felype@yadfilmes.com.br | E12: Em | F12: 46254
B13: Versão | C13: v1 | E13: Situação | F13: EM ANDAMENTO
B15: 1. ENTRADAS — o que o cliente paga
B16: DESCRIÇÃO | C16: VALOR | D16: DATA PREVISTA | E16: STATUS | F16: OBS
B17: Live AMIRA — valor com desconto de parceiro | C17: 6791.5 | E17: A RECEBER | F17: tabela 7.990,00 com 15% de desconto parceiro Estúdio São Paulo (−1.198,50) · orçamento de 06/08/2026 · imposto em 16% por padrão da casa — CONFIRMAR se este job sai com nota
B21: TOTAL ENTRADAS (BRUTO) | C21: =SUM(C17:C20)
B22: IMPOSTO (%) ← edite aqui se mudar | C22: 0.16 | D22: COMISSÃO (%) sobre a entrada líquida ← edite aqui | F22: 0.15
B23: (−) IMPOSTO | C23: =ROUND(C21*C22,2)
B24: (=) ENTRADA LÍQUIDA — é com isso que se paga tudo | C24: =C21-C23
B26: 2. SAÍDAS POR ÁREA — vem sozinho da aba SAÍDAS
B27: ÁREA | C27: VALOR | D27: % DA LÍQUIDA | E27: PAGO | F27: A PAGAR
B28: =IF(AREAS!$A$2="","",AREAS!$A$2) | C28: =IF(B28="","",SUMIF(SAIDAS!$B$6:$B$500,B28,SAIDAS!$G$6:$G$500)) | D28: =IF(OR(B28="",$C$24=0),"",C28/$C$24) | E28: =IF(B28="","",SUMIFS(SAIDAS!$G$6:$G$500,SAIDAS!$B$6:$B$500,B28,SAIDAS!$H$6:$H$500,"PAGO")) | F28: =IF(B28="","",C28-E28)
B29: =IF(AREAS!$A$3="","",AREAS!$A$3) | C29: =IF(B29="","",SUMIF(SAIDAS!$B$6:$B$500,B29,SAIDAS!$G$6:$G$500)) | D29: =IF(OR(B29="",$C$24=0),"",C29/$C$24) | E29: =IF(B29="","",SUMIFS(SAIDAS!$G$6:$G$500,SAIDAS!$B$6:$B$500,B29,SAIDAS!$H$6:$H$500,"PAGO")) | F29: =IF(B29="","",C29-E29)
B30: =IF(AREAS!$A$4="","",AREAS!$A$4) | C30: =IF(B30="","",SUMIF(SAIDAS!$B$6:$B$500,B30,SAIDAS!$G$6:$G$500)) | D30: =IF(OR(B30="",$C$24=0),"",C30/$C$24) | E30: =IF(B30="","",SUMIFS(SAIDAS!$G$6:$G$500,SAIDAS!$B$6:$B$500,B30,SAIDAS!$H$6:$H$500,"PAGO")) | F30: =IF(B30="","",C30-E30)
B31: =IF(AREAS!$A$5="","",AREAS!$A$5) | C31: =IF(B31="","",SUMIF(SAIDAS!$B$6:$B$500,B31,SAIDAS!$G$6:$G$500)) | D31: =IF(OR(B31="",$C$24=0),"",C31/$C$24) | E31: =IF(B31="","",SUMIFS(SAIDAS!$G$6:$G$500,SAIDAS!$B$6:$B$500,B31,SAIDAS!$H$6:$H$500,"PAGO")) | F31: =IF(B31="","",C31-E31)
B32: =IF(AREAS!$A$6="","",AREAS!$A$6) | C32: =IF(B32="","",SUMIF(SAIDAS!$B$6:$B$500,B32,SAIDAS!$G$6:$G$500)) | D32: =IF(OR(B32="",$C$24=0),"",C32/$C$24) | E32: =IF(B32="","",SUMIFS(SAIDAS!$G$6:$G$500,SAIDAS!$B$6:$B$500,B32,SAIDAS!$H$6:$H$500,"PAGO")) | F32: =IF(B32="","",C32-E32)
B33: =IF(AREAS!$A$7="","",AREAS!$A$7) | C33: =IF(B33="","",SUMIF(SAIDAS!$B$6:$B$500,B33,SAIDAS!$G$6:$G$500)) | D33: =IF(OR(B33="",$C$24=0),"",C33/$C$24) | E33: =IF(B33="","",SUMIFS(SAIDAS!$G$6:$G$500,SAIDAS!$B$6:$B$500,B33,SAIDAS!$H$6:$H$500,"PAGO")) | F33: =IF(B33="","",C33-E33)
B34: =IF(AREAS!$A$8="","",AREAS!$A$8) | C34: =IF(B34="","",SUMIF(SAIDAS!$B$6:$B$500,B34,SAIDAS!$G$6:$G$500)) | D34: =IF(OR(B34="",$C$24=0),"",C34/$C$24) | E34: =IF(B34="","",SUMIFS(SAIDAS!$G$6:$G$500,SAIDAS!$B$6:$B$500,B34,SAIDAS!$H$6:$H$500,"PAGO")) | F34: =IF(B34="","",C34-E34)
B35: =IF(AREAS!$A$9="","",AREAS!$A$9) | C35: =IF(B35="","",SUMIF(SAIDAS!$B$6:$B$500,B35,SAIDAS!$G$6:$G$500)) | D35: =IF(OR(B35="",$C$24=0),"",C35/$C$24) | E35: =IF(B35="","",SUMIFS(SAIDAS!$G$6:$G$500,SAIDAS!$B$6:$B$500,B35,SAIDAS!$H$6:$H$500,"PAGO")) | F35: =IF(B35="","",C35-E35)
B36: =IF(AREAS!$A$10="","",AREAS!$A$10) | C36: =IF(B36="","",SUMIF(SAIDAS!$B$6:$B$500,B36,SAIDAS!$G$6:$G$500)) | D36: =IF(OR(B36="",$C$24=0),"",C36/$C$24) | E36: =IF(B36="","",SUMIFS(SAIDAS!$G$6:$G$500,SAIDAS!$B$6:$B$500,B36,SAIDAS!$H$6:$H$500,"PAGO")) | F36: =IF(B36="","",C36-E36)
B37: =IF(AREAS!$A$11="","",AREAS!$A$11) | C37: =IF(B37="","",SUMIF(SAIDAS!$B$6:$B$500,B37,SAIDAS!$G$6:$G$500)) | D37: =IF(OR(B37="",$C$24=0),"",C37/$C$24) | E37: =IF(B37="","",SUMIFS(SAIDAS!$G$6:$G$500,SAIDAS!$B$6:$B$500,B37,SAIDAS!$H$6:$H$500,"PAGO")) | F37: =IF(B37="","",C37-E37)
B38: =IF(AREAS!$A$12="","",AREAS!$A$12) | C38: =IF(B38="","",SUMIF(SAIDAS!$B$6:$B$500,B38,SAIDAS!$G$6:$G$500)) | D38: =IF(OR(B38="",$C$24=0),"",C38/$C$24) | E38: =IF(B38="","",SUMIFS(SAIDAS!$G$6:$G$500,SAIDAS!$B$6:$B$500,B38,SAIDAS!$H$6:$H$500,"PAGO")) | F38: =IF(B38="","",C38-E38)
B39: SEM ÁREA — classificar na aba SAÍDAS | C39: =ROUND(SUM(SAIDAS!$G$6:$G$500)-SUM(C28:C38),2)
B40: TOTAL SAÍDAS | C40: =ROUND(SUM(SAIDAS!$G$6:$G$500),2) | D40: =IF($C$24=0,"",C40/$C$24) | E40: =SUMIF(SAIDAS!$H$6:$H$500,"PAGO",SAIDAS!$G$6:$G$500) | F40: =C40-E40
B42: 3. RESULTADO
B43: ENTRADA LÍQUIDA | C43: =C24
B44: (−) TOTAL SAÍDAS | C44: =C40
B45: (=) LUCRO DA YAD | C45: =C24-C40
B46: MARGEM (sobre a entrada bruta) | C46: =IF(C21=0,"",C45/C21)
B48: 4. CAIXA — o que já andou e o que falta
C49: JÁ ANDOU | D49: FALTA
B50: ENTRADAS (recebido / a receber) | C50: =SUMIF(E17:E20,"RECEBIDO",C17:C20) | D50: =C21-C50
...

Sheet AREAS
A1: ÁREAS DE GASTO
A2: EQUIPE | C2: Área nova? Escreva na primeira linha amarela.
A3: EQUIPAMENTO E TRANSMISSÃO | C3: Ela aparece sozinha na listinha da aba SAÍDAS e vira uma linha no RESUMO.
A4: TRANSPORTE E LOGÍSTICA | C4: Não apague área que já tem gasto lançado — o RESUMO perde a linha.
A5: ALIMENTAÇÃO
A6: PRODUÇÃO E DIVERSOS
A7: COMISSÃO

Sheet SAIDAS
B2: SAÍDAS — um gasto por linha
B3: Como usar: 1) escreva o gasto numa linha vazia 2) escolha a ÁREA na listinha da célula 3) preencha QTD e VALOR UNITÁRIO — o TOTAL e o RESUMO se viram sozinhos.
B5: ÁREA | C5: DESCRIÇÃO / QUEM | D5: FUNÇÃO / DETALHE | E5: QTD | F5: VALOR UNITÁRIO | G5: TOTAL | H5: STATUS | I5: DATA PGTO | J5: OBS
B6: EQUIPE | C6: Emerson | D6: Responsável pela live — direção técnica e switcher | E6: 1 | F6: 1000 | G6: =IF(OR(E6="",F6=""),"",ROUND(E6*F6,2)) | H6: A PAGAR | J6: valor real informado pelo Felype · Emerson tem cachê cheio, não é equipe zerada
B7: EQUIPE | C7: Isa | D7: Cinegrafista e montagem | E7: 1 | F7: 1000 | G7: =IF(OR(E7="",F7=""),"",ROUND(E7*F7,2)) | H7: A PAGAR | J7: valor real informado pelo Felype · mesma diária de cinegrafista de operação do YAH CHURCH
B8: EQUIPE | C8: Lucas | D8: Cinegrafista e assistente | E8: 1 | F8: 500 | G8: =IF(OR(E8="",F8=""),"",ROUND(E8*F8,2)) | H8: A PAGAR | J8: valor real informado pelo Felype · no YAH CHURCH era assistente a 250; subiu para 500 acumulando câmera
B9: EQUIPAMENTO E TRANSMISSÃO | C9: 2 câmeras 4K, ATEM mini, torre vMix, interface de áudio, cabeamento e monitor | D9: parque próprio | E9: 1 | F9: 0 | G9: =IF(OR(E9="",F9=""),"",ROUND(E9*F9,2)) | J9: equipamento 100% da YAD — é daqui que vem o lucro deste job
B10: EQUIPAMENTO E TRANSMISSÃO | C10: Internet dedicada | D10: link de transmissão | E10: 1 | F10: 0 | G10: =IF(OR(E10="",F10=""),"",ROUND(E10*F10,2)) | J10: o orçamento diz que é responsabilidade do cliente — sem custo para a YAD
B11: TRANSPORTE E LOGÍSTICA | C11: Transporte do equipamento e deslocamento | D11: ida e volta no dia | E11: 2 | F11: 350 | G11: =IF(OR(E11="",F11=""),"",ROUND(E11*F11,2)) | H11: A PAGAR | J11: ADICIONADO — 350 por trecho, padrão da casa. Se for na van com a própria equipe, zerar.
B12: ALIMENTAÇÃO | C12: Café da manhã da equipe | D12: evento 8h às 13h, sem almoço | E12: 1 | F12: 100 | G12: =IF(OR(E12="",F12=""),"",ROUND(E12*F12,2)) | H12: A PAGAR | J12: valor fechado informado pelo Felype · se for R$ 100 POR PESSOA, mudar a QTD para 3
B13: PRODUÇÃO E DIVERSOS | C13: Mídia e guarda da gravação | D13: se a live também for gravada | E13: 1 | G13: =IF(OR(E13="",F13=""),"",ROUND(E13*F13,2)) | H13: A PAGAR | J13: ADICIONADO — o orçamento vende transmissão; se ficar arquivo gravado, alguém guarda. Zerar se não houver entrega de arquivo.
B14: COMISSÃO | C14: Comissão comercial — a definir quem | D14: % sobre a entrada líquida | E14: 1 | F14: =ROUND(RESUMO!$C$24*RESUMO!$F$22,2) | G14: =IF(OR(E14="",F14=""),"",ROUND(E14*F14,2)) | H14: A PAGAR | J14: =TEXT(RESUMO!$F$22,"0.0%")&" da entrada líquida (RESUMO!C24)"
G15: =IF(OR(E15="",F15=""),"",ROUND(E15*F15,2))
G16: =IF(OR(E16="",F16=""),"",ROUND(E16*F16,2))
G17: =IF(OR(E17="",F17=""),"",ROUND(E17*F17,2))
G18: =IF(OR(E18="",F18=""),"",ROUND(E18*F18,2))
G19: =IF(OR(E19="",F19=""),"",ROUND(E19*F19,2))
G20: =IF(OR(E20="",F20=""),"",ROUND(E20*F20,2))
G21: =IF(OR(E21="",F21=""),"",ROUND(E21*F21,2))
G22: =IF(OR(E22="",F22=""),"",ROUND(E22*F22,2))
G23: =IF(OR(E23="",F23=""),"",ROUND(E23*F23,2))
G24: =IF(OR(E24="",F24=""),"",ROUND(E24*F24,2))
G25: =IF(OR(E25="",F25=""),"",ROUND(E25*F25,2))
G26: =IF(OR(E26="",F26=""),"",ROUND(E26*F26,2))
... G500: =IF(OR(E500="",F500=""),"",ROUND(E500*F500,2))
